File: XRD/180820 ETB-001 Layered Test/110C Anneal Wiley_quick gonio scan_3.xrdml
<?xml version="1.0" encoding="UTF-8"?>
<xrdMeasurements xmlns="http://www.xrdml.com/XRDMeasurement/1.5" xmlns:xsi="http://www.w3.org/2001/XMLSchema-instance" xsi:schemaLocation="http://www.xrdml.com/XRDMeasurement/1.5 http://www.xrdml.com/XRDMeasurement/1.5/XRDMeasurement.xsd" status="Completed">
	<comment>
		<entry>Configuration=Stage Flat Samples, Owner=User-1, Creation date=6/6/2014 1:31:02 PM</entry>
		<entry>Goniometer=Theta/Theta; Minimum step size 2Theta:0.0001; Minimum step size Omega:0.0001</entry>
		<entry>Sample stage=Stage for flat samples/holders</entry>
		<entry>Diffractometer system=EMPYREAN</entry>
		<entry>Measurement program=C:\PANalytical\Data Collector\Programs\Wiley_quick gonio scan.xrdmp, Identifier={A69CF207-6E3A-42E5-A795-621C7C9217BF}</entry>
	</comment>
	<sample type="To be analyzed">
		<id></id>
		<name></name>
		<preparedBy></preparedBy>
	</sample>
	<xrdMeasurement measurementType="Scan" status="Completed" sampleMode="Reflection">
		<comment>
			<entry/>
		</comment>
		<usedWavelength intended="K-Alpha 1">
			<kAlpha1 unit="Angstrom">1.5405980</kAlpha1>
			<kAlpha2 unit="Angstrom">1.5444260</kAlpha2>
			<kBeta unit="Angstrom">1.3922500</kBeta>
			<ratioKAlpha2KAlpha1>0.5000</ratioKAlpha2KAlpha1>
		</usedWavelength>
		<incidentBeamPath>
			<radius unit="mm">240.00</radius>
			<xRayTube id="1010048" name="Empyrean Cu LFF HR (9430 033 7310x) DK402532">
				<tension unit="kV">45</tension>
				<current unit="mA">40</current>
				<anodeMaterial>Cu</anodeMaterial>
				<focus type="Line">
					<length unit="mm">12.0</length>
					<width unit="mm">0.4</width>
					<takeOffAngle unit="deg">4.4</takeOffAngle>
				</focus>
			</xRayTube>
			<xRayMirror id="27020009" name="Bragg-Brentano HD" hybrid="false">
				<crystal type="Graded" shape="Flat">BB/HD</crystal>
				<acceptanceAngle unit="deg">0.800</acceptanceAngle>
				<length unit="mm">55.3</length>
			</xRayMirror>
			<sollerSlit id="21010001" name="Soller slits 0.02 rad.">
				<opening unit="rad">0.0200</opening>
			</sollerSlit>
			<mask id="22030009" name="Fixed mask 10 mm">
				<width unit="mm">10.00</width>
			</mask>
			<antiScatterSlit id="22010003" name="Fixed slit 1°" xsi:type="fixedAntiScatterSlitType">
				<height unit="mm">1.52</height>
			</antiScatterSlit>
			<divergenceSlit id="22010005" name="Fixed slit 1/4°" xsi:type="fixedDivergenceSlitType">
				<distanceToSample unit="mm">140.00</distanceToSample>
				<height unit="mm">0.38</height>
			</divergenceSlit>
		</incidentBeamPath>
		<diffractedBeamPath>
			<radius unit="mm">240.00</radius>
			<antiScatterSlit id="22090004" name="AS slit 5.5 mm (X'Celerator)" xsi:type="fixedAntiScatterSlitType">
				<height unit="mm">5.50</height>
			</antiScatterSlit>
			<sollerSlit id="21020002" name="Large Soller slits 0.02 rad.">
				<opening unit="rad">0.0200</opening>
			</sollerSlit>
			<detector id="7010012" name="X'Celerator Scientific" xsi:type="rtmsDetectorType">
				<phd>
					<lowerLevel unit="%">38.5</lowerLevel>
					<upperLevel unit="%">80.0</upperLevel>
				</phd>
				<mode>Scanning</mode>
				<activeLength unit="deg">2.1221</activeLength>
			</detector>
		</diffractedBeamPath>
		<scan appendNumber="0" mode="Continuous" scanAxis="Gonio" status="Completed">
			<header>
				<startTimeStamp>2018-08-20T19:53:00-04:00</startTimeStamp>
				<endTimeStamp>2018-08-20T20:01:22-04:00</endTimeStamp>
				<author>
					<name>User</name>
				</author>
				<source>
					<applicationSoftware version="4.4a">Data Collector</applicationSoftware>
					<instrumentControlSoftware version="7.4  20131206">EMPYREAN</instrumentControlSoftware>
					<instrumentID>0000000011157113</instrumentID>
				</source>
			</header>
			<dataPoints>
				<positions axis="2Theta" unit="deg">
					<startPosition>3.00835563</startPosition>
					<endPosition>69.98712170</endPosition>
				</positions>
				<positions axis="Omega" unit="deg">
					<startPosition>1.50417782</startPosition>
					<endPosition>34.99356085</endPosition>
				</positions>
				<commonCountingTime unit="seconds">15.240</commonCountingTime>
				<intensities unit="counts">301 292 291 300 280 283 273 231 265 263 259 253 246 261 216 225 249 246 223 242 237 232 235 235 252 243 221 229 227 212 232 221 221 217 201 215 203 206 224 198 200 218 222 200 201 216 201 187 200 194 186 188 199 195 194 203 197 204 204 181 177 196 185 188 186 198 168 143 199 185 162 159 170 186 167 191 179 164 174 181 160 160 195 152 196 213 181 183 157 159 163 152 170 149 161 159 169 164 155 152 160 175 144 150 157 165 152 144 152 183 145 153 147 174 162 146 147 177 141 171 137 146 157 156 159 155 124 157 150 137 151 136 151 144 136 136 124 149 146 127 136 152 123 159 147 141 143 139 113 126 157 123 128 140 137 116 121 121 164 118 161 148 128 132 144 135 143 148 156 152 132 147 146 136 157 157 132 113 106 112 118 138 126 123 104 114 112 137 109 134 122 116 117 98 120 118 113 101 127 108 104 115 93 115 105 118 111 112 115 113 105 92 92 96 100 139 106 120 106 101 101 105 102 93 126 132 115 101 114 110 92 85 102 98 105 96 144 99 94 78 99 108 91 92 103 106 112 102 112 104 87 99 91 101 96 92 103 96 88 110 112 93 97 82 100 104 96 78 77 91 96 79 82 90 88 88 88 91 93 76 88 98 102 84 91 89 89 105 72 90 85 97 92 68 78 86 78 85 93 90 100 74 98 86 91 88 79 73 76 80 94 86 87 102 73 91 84 97 108 72 92 92 87 129 81 77 85 78 78 98 91 86 77 93 84 96 89 75 94 78 87 70 89 84 85 74 81 72 102 52 86 77 92 84 99 86 79 87 98 90 97 86 74 65 89 70 64 85 77 81 70 72 69 75 64 75 79 98 82 68 61 73 84 86 87 77 85 72 74 79 56 101 60 79 64 85 82 73 74 66 82 75 68 97 85 75 80 69 96 65 70 63 63 78 67 79 91 72 61 78 88 78 82 62 65 85 79 85 75 58 93 93 73 72 66 66 62 79 77 80 74 82 70 74 79 78 77 84 62 89 73 66 77 78 73 89 79 78 56 76 77 88 75 78 82 80 80 84 77 79 80 60 81 82 99 66 73 105 69 80 53 98 82 84 88 86 68 82 62 79 70 90 86 65 99 78 78 87 105 78 88 82 101 91 112 92 94 82 100 93 98 100 88 98 118 89 124 113 103 101 92 108 121 93 97 110 108 130 127 124 117 145 151 126 125 136 121 143 160 145 163 141 179 174 169 217 224 233 229 245 261 252 245 288 336 347 362 395 445 516 575 612 672 751 828 901 1045 1162 1318 1467 1581 1753 1902 2036 2253 2408 2517 2696 2682 2605 2587 2579 2425 2295 2102 1961 1825 1613 1424 1304 1068 982 856 775 609 516 493 447 426 354 332 334 277 230 266 213 196 174 169 157 168 139 138 138 136 169 134 116 117 101 101 98 67 115 94 91 94 100 97 82 78 76 77 98 104 84 87 89 84 81 64 86 93 76 68 103 96 92 112 91 106 104 89 112 141 138 134 153 212 240 287 445 499 681 896 1122 1192 1073 878 633 453 337 248 176 156 139 126 111 126 99 79 96 75 86 73 58 57 80 65 80 58 58 73 77 61 67 64 56 54 68 70 43 66 51 56 55 60 56 66 56 65 77 54 73 60 57 49 52 54 53 65 63 55 57 58 55 46 55 65 55 54 48 46 45 63 57 53 69 48 58 62 61 63 61 45 46 58 49 48 51 52 50 54 51 54 72 60 62 52 43 61 61 56 54 66 70 54 52 54 61 63 53 60 56 45 61 50 53 63 38 46 50 61 45 68 50 64 67 64 61 63 50 55 61 64 53 64 58 46 56 62 60 63 57 62 60 54 62 68 62 69 58 60 60 73 60 63 62 63 48 58 58 62 65 50 65 66 53 48 65 70 70 53 63 44 52 75 48 80 55 64 63 60 51 57 57 60 65 62 78 50 69 72 54 66 73 58 60 77 57 53 73 45 65 79 57 51 63 66 66 58 50 55 64 56 62 61 48 58 66 67 57 77 58 87 67 53 66 66 70 64 67 66 65 74 68 56 55 77 55 66 74 63 63 68 74 69 69 57 65 73 65 67 65 60 75 82 65 74 67 64 75 58 72 63 65 67 53 57 69 88 72 76 64 67 65 77 75 85 65 68 81 70 77 68 90 58 68 65 78 80 73 81 80 69 64 72 85 67 78 65 66 86 96 68 67 62 84 80 74 84 84 75 75 72 60 77 74 66 78 66 72 80 92 78 88 72 78 100 79 87 77 74 79 73 87 86 78 82 80 74 81 82 91 79 88 92 98 81 63 93 106 104 103 114 129 132 189 205 162 209 170 174 128 103 91 96 85 78 75 76 89 89 81 80 79 84 100 85 89 97 79 76 80 74 78 94 85 85 72 84 86 90 96 73 86 85 96 80 86 108 96 99 80 94 88 73 80 93 73 86 80 87 78 84 75 96 89 96 100 81 79 99 73 84 81 103 106 93 117 84 78 110 80 87 88 90 97 87 94 93 92 86 100 94 78 84 108 104 90 91 75 92 89 103 89 103 92 93 94 125 96 84 94 96 104 91 92 104 76 93 105 82 93 103 125 87 94 84 85 96 102 90 101 88 100 86 113 74 100 97 97 99 109 99 87 104 126 102 96 84 103 99 98 90 90 87 84 93 93 101 93 121 98 124 108 96 92 96 104 94 96 87 92 101 103 130 102 105 120 100 106 91 96 111 98 100 110 99 124 84 106 89 79 101 77 114 79 98 120 109 94 101 114 103 108 112 111 91 112 92 117 109 124 143 148 159 173 172 160 160 143 126 139 98 106 109 113 99 101 103 116 94 109 120 100 122 82 90 111 98 100 98 103 93 102 101 93 96 102 96 108 97 109 93 99 99 99 108 102 108 106 93 113 110 99 102 108 104 99 106 118 108 117 122 153 189 163 182 163 152 114 141 109 129 117 78 99 128 110 102 102 94 91 97 100 104 109 104 96 89 110 103 101 103 113 103 82 86 134 111 105 100 110 111 105 108 120 127 135 113 122 135 134 122 157 158 161 174 138 165 171 162 175 175 153 158 147 163 149 159 144 111 130 128 129 122 97 130 125 108 120 84 114 106 105 100 101 88 121 98 77 94 110 99 99 100 89 104 82 91 84 93 88 99 84 118 99 110 85 100 98 87 100 89 117 97 97 84 87 87 100 84 78 97 75 96 88 112 100 94 93 100 87 91 86 81 92 96 94 89 101 96 68 94 99 81 97 88 88 101 106 94 104 87 87 88 73 106 90 104 90 84 105 73 76 99 80 85 76 86 86 87 90 93 87 96 76 87 100 90 75 85 106 101 98 115 79 93 88 84 94 87 93 89 106 81 77 81 77 79 123 88 76 80 72 88 85 100 92 82 106 87 85 102 108 94 105 92 89 91 141 114 98 100 112 93 124 117 123 118 118 118 128 141 147 147 164 183 230 272 356 443 453 419 424 358 317 291 254 215 155 135 120 115 104 99 114 104 98 94 88 111 99 94 111 90 73 106 87 89 90 100 89 94 84 103 93 105 87 88 81 68 78 90 90 88 84 87 89 99 92 88 82 94 81 79 73 89 88 79 93 94 91 81 78 72 77 69 109 84 76 116 78 84 96 68 82 85 78 84 97 98 78 80 81 86 67 78 74 98 84 97 76 80 80 66 62 98 69 80 72 98 90 92 88 91 85 85 76 90 76 57 73 88 82 63 86 90 81 79 87 85 75 67 82 73 79 74 89 92 81 62 87 84 79 89 74 91 79 89 89 70 88 76 75 81 86 78 100 80 97 80 72 84 86 101 87 69 70 85 70 84 56 85 77 76 55 86 78 69 98 85 106 63 82 60 78 69 84 73 75 73 79 67 64 75 89 89 86 91 97 81 99 77 98 76 80 91 96 106 112 133 134 151 186 232 272 308 306 313 276 230 200 188 156 152 109 102 113 75 77 72 90 69 91 81 85 81 85 65 70 66 90 61 66 86 74 70 93 65 77 64 62 64 69 72 72 72 93 74 70 60 60 55 50 67 60 66 56 75 73 72 69 73 67 64 70 78 60 72 63 57 82 73 62 65 61 85 93 69 65 66 67 64 72 63 57 64 58 72 70 67 77 65 65 68 70 58 72 64 65 68 76 69 60 76 58 75 63 77 56 61 73 63 72 77 70 69 72 58 61 66 65 76 45 53 56 48 65 56 37 50 69 51 53 54 68 63 58 67 65 55 55 77 58 66 56 66 52 78 55 64 61 67 57 58 60 66 51 79 65 81 52 63 55 79 55 52 64 50 67 60 48 62 65 57 58 45 52 52 62 58 56 60 57 49 56 73 72 58 76 80 90 76 79 103 74 63 85 74 60 57 57 60 57 52 40 58 53 45 43 54 42 61 49 56 54 49 56 51 54 61 50 50 53 43 43 57 55 60 43 57 45 52 62 64 48 56 64 40 48 50 40 45 57 60 49 51 60 55 61 52 42 46 68 40 55 57 57 44 48 57 57 45 45 57 50 63 42 51 43 50 39 66 49 62 43 53 51 54 53 46 56 44 52 38 50 68 53 50 49 40 49 44 38 38 51 49 39 38 53 55 53 50 49 46 50 42 55 40 61 52 62 43 55 61 56 33 45 60 54 48 34 55 51 53 49 61 45 54 43 56 57 58 57 41 56 64 42 68 54 68 45 48 57 62 48 57 52 53 44 44 51 60 55 51 40 42 53 36 57 61 61 49 44 51 63 52 49 48 50 45 55 51 52 62 56 67 56 56 73 51 55 68 69 64 64 58 67 90 68 77 93 105 94 101 123 130 132 143 168 160 180 183 229 219 242 266 222 270 291 240 256 293 271 288 260 233 239 239 165 146 189 143 134 143 98 104 111 79 96 97 82 73 75 84 62 69 51 67 54 63 55 50 51 49 43 54 45 50 62 62 52 48 46 51 53 64 39 57 54 69 50 76 60 54 61 45 53 41 42 50 49 49 55 50 52 38 34 46 43 53 48 43 48 46 25 43 52 51 52 46 40 39 44 49 34 45 39 42 36 42 33 56 39 53 44 36 51 55 48 38 52 30 55 54 41 40 57 62 76 51 81 64 63 62 60 58 66 65 92 97 126 145 168 133 100 99 94 87 91 84 81 49 65 53 57 50 44 64 41 55 43 54 52 44 54 50 51 39 41 53 50 56 43 34 37 38 42 37 60 44 52 42 43 48 39 49 55 45 51 48 54 40 53 45 36 39 48 28 33 36 46 45 37 46 56 44 42 48 34 48 38 41 41 38 50 37 48 36 46 44 31 40 31 43 37 43 43 39 48 33 63 34 38 43 57 43 49 39 49 37 42 34 33 46 49 46 41 39 40 56 51 41 51 53 56 61 57 70 74 55 77 45 45 57 62 55 42 43 41 51 42 50 60 42 55 48 45 44 46 52 60 45 56 53 61 48 58 56 54 45 60 70 81 89 62 79 77 77 65 73 61 56 65 58 66 42 40 51 51 45 33 31 36 41 42 40 31 52 49 49 48 39 46 40 34 46 41 37 41 39 30 34 34 52 38 41 33 39 42 39 33 41 42 41 36 40 39 34 42 48 48 36 37 39 37 57 36 34 37 34 33 50 29 37 38 28 43 38 44 43 40 45 44 38 44 37 43 34 29 53 39 55 43 36 41 37 34 29 42 41 49 40 41 21 37 55 45 36 28 33 40 32 34 48 42 37 36 36 28 30 38 33 34 45 42 44 48 43 30 49 46 34 40 42 48 43 43 37 30 39 36 33 39 48 52 43 28 48 40 36 40 38 50 37 38 60 43 39 41 41 46 45 53 48 48 43 38 49 46 40 52 41 34 31 40 32 46 32 44 53 32 49 42 41 41 28 39 52 54 43 31 30 36 27 40 38 42 39 37 37 31 36 53 42 29 42 31 38 48 41 38 34 29 32 32 33 40 39 32 26 34 42 32 40 41 34 31 45 32 42 33 38 26 40 36 31 32 38 39 28 41 42 37 30 42 38 41 37 40 41 39 53 38 39 39 38 48 46 41 44 38 36 42 42 41 39 31 38 33 34 31 45 31 25 46 45 34 34 52 41 38 36 33 21 27 34 25 32 45 41 43 33 39 28 34 37 28 38 36 37 45 40 38 27 31 41 44 41 43 27 31 42 38 34 29 43 28 39 40 36 39 33 33 41 32 29 34 31 44 42 38 38 44 44 37 33 36 26 39 40 38 30 38 28 40 32 32 34 32 36 31 37 39 38 33 44 25 32 34 29 48 31 50 27 46 28 30 38 32 33 34 33 41 34 31 41 42 38 36 54 26 33 37 42 21 32 40 32 37 30 30 29 36 21 31 36 34 33 31 41 29 40 46 46 31 32 36 29 39 29 49 39 38 37 30 44 45 28 43 46 39 44 74 44 51 49 31 50 49 51 51 32 36 39 40 34 20 46 33 24 37 36 36 31 29 33 29 41 41 37 36 43 38 33 34 41 39 22 31 40 30 40 37 38 36 43 37 31 43 34 36 53 32 43 33 48 41 41 42 30 31 28 31 32 43 43 27 38 40 43 34 38 41 29 39 41 34 49 45 39 43 49 30 34 37 37 34 46 44 49 49 50 49 42 33 60 41 64 57 51 54 62 67 65 64 54 61 70 82 81 100 69 111 104 109 106 117 139 136 117 144 174 171 165 137 143 183 169 150 148 170 157 146 139 140 153 115 130 121 115 127 125 92 108 89 86 99 88 80 74 72 58 70 72 58 60 63 44 46 48 43 41 41 40 46 38 50 37 60 31 40 39 49 46 45 44 44 32 49 39 52 53 39 40 45 41 37 39 34 45 42 39 39 48 29 32 33 46 42 26 38 43 28 41 32 25 30 56 36 33 41 41 29 26 32 30 30 30 43 43 31 24 32 32 37 37 28 41 36 42 32 40 28 34 33 29 29 33 36 37 30 28 49 36 36 29 33 27 29 42 43 37 24 27 33 26 26 43 36 30 27 39 36 40 37 45 45 32 28 32 42 38 26 36 39 34 38 33 27 31 32 20 41 28 28 42 42 41 38 29 38 38 27 29 45 41 46 34 27 36 43 33 36 36 45 41 36 34 36 40 45 34 26 25 42 36 43 37 32 33 38 30 30 32 37 31 30 55 40 39 44 41 45 21 37 38 19 34 31 28 36 40 43 34 41 38 24 42 38 38 30 33 28 29 28 37 36 28 32 29 38 30 32 41 28 38 36 33 29 32 38 31 33 38 28 40 32 34 40 40 29 27 38 46 38 34 21 39 31 40 29 28 27 29 31 34 36 42 37 40 36 46 38 30 30 34 37 44 28 36 33 29 27 38 36 34 32 28 38 44 39 27 22 30 34 27 27 27 32 34 37 26 54 26 22 36 29 53 27 32 31 38 34 32 31 34 36 32 40 37 31 42 39 33 32 34 46 33 29 26 37 37 30 24 32 42 24 29 32 41 29 37 28 29 31 31 27 37 32 32 46 27 30 29 22 30 40 38 34 45 41 34 37 43 36 36 34 37 41 30 43 36 29 30 38 32 36 45 34 36 40 40 38 28 39 54 36 40 42 39 38 50 52 34 27 36 31 48 36 40 40 44 28 21 50 34 40 44 25 37 31 41 25 36 40 26 28 39 33 40 36 29 32 33 33 34 27 37 49 29 28 29 30 30 32 31 41 43 30 34 30 29 29 34 31 34 41 29 39 33 46 32 43 36 34 46 36 37 34 20 29 29 31 37 28 38 29 37 25 29 36 42 36 51 45 29 29 44 42 29 24 34 34 44 33 33 27 27 30 33 28 30 37 26 37 32 37 44 46 42 36 42 43 44 50 34 36 48 54 54 48 54 44 46 41 31 40 53 33 44 41 38 50 31 40 33 46 33 42 38 37 39 33 46 39 33 39 28 42 31 41 31 25 41 21 38 42 31 30 21 43 34 33 36 27 38 28 31 39 31 34 29 25 40 39 33 44 36 41 30 29 41 53 41 31 36 42 31 52 41 29 32 40 39 30 31 36 43 45 29 34 33 39 33 32 40 17 34 38 33 40 33 38 40 30 34 45 29 33 19 33 28 32 31 42 30 39 38 36 28 28 28 54 42 36 31 34 42 41 36 30 41 30 38 43 34 40 36 34 29 41 31 42 28 38 39 30 34 34 38 37 36 31 37 38 38 42 31 37 26 28 37 34 28 46 39 43 46 24 22 31 28 26 41 37 31 44 51 34 36 41 36 42 36 34 37 33 42 38 38 38 37 34 34 40 33 27 45 40 38 32 33 25 33 29 27 32 34 31 34 37 34 28 42 40 30 30 30 37 31 32 37 44 37 42 36 34 28 30 27 37 50 27 30 36 38 28 25 42 39 43 36 28 28 31 32 42 25 26 44 46 20 51 37 34 27 33 33 36 28 33 44 34 32 49 38 38 30 41 31 29 27 38 30 37 31 26 31 37 28 38 42 31 32 41 34 37 28 29 41 36 34 30 26 34 24 26 46 33 22 29 50 31 40 37 45 20 32 28 48 28 46 38 33 39 42 30 39 32 27 30 40 38 42 39 36 37 29 33 32 44 33 34 34 36 34 29 24 33 31 32 24 37 32 36 41 41 39 41 26 27 37 29 36 29 42 33 34 44 20 31 39 41 33 34 28 27 43 32 28 31 33 42 33 36 32 18 31 28 29 33 46 30 42 42 26 36 39 24 28 32 32 34 36 32 42 34 27 36 29 33 39 46 31 32 46 33 38 30 34 31 40 39 28 43 34 27 39 29 32 20 28 38 27 40 43 30 45 40 32 32 42 39 41 26 46 37 32 31 32 40 39 28 34 28 32 33 36 24 33 32 40 27 30 32 19 43 45 43 43 33 38 41 38 29 30 46 42 33 29 37 36 41 30 34 26 29 31 21 36 28 26 32 28 32 34 19 30 28 26 20 22 32 32 42 34 41 37 33 24 44 24 24 14 29 31 36 21 29 34 34 25 38 37 28 21 36 39 36 28 27 39 31 27 32 24 27 21 25 39 33 33 37 27 34 28 31 39 27 29 34 17 22 30 25 28 28 32 41 39 26 34 24 28 27 21</intensities>
			</dataPoints>
		</scan>
	</xrdMeasurement>
</xrdMeasurements>