File: XRD/180821 ETB-002 Layered Test/110C Wiley_quick gonio scan_4.xrdml
<?xml version="1.0" encoding="UTF-8"?>
<xrdMeasurements xmlns="http://www.xrdml.com/XRDMeasurement/1.5" xmlns:xsi="http://www.w3.org/2001/XMLSchema-instance" xsi:schemaLocation="http://www.xrdml.com/XRDMeasurement/1.5 http://www.xrdml.com/XRDMeasurement/1.5/XRDMeasurement.xsd" status="Completed">
	<comment>
		<entry>Configuration=Stage Flat Samples, Owner=User-1, Creation date=6/6/2014 1:31:02 PM</entry>
		<entry>Goniometer=Theta/Theta; Minimum step size 2Theta:0.0001; Minimum step size Omega:0.0001</entry>
		<entry>Sample stage=Stage for flat samples/holders</entry>
		<entry>Diffractometer system=EMPYREAN</entry>
		<entry>Measurement program=C:\PANalytical\Data Collector\Programs\Wiley_quick gonio scan.xrdmp, Identifier={A69CF207-6E3A-42E5-A795-621C7C9217BF}</entry>
	</comment>
	<sample type="To be analyzed">
		<id></id>
		<name></name>
		<preparedBy></preparedBy>
	</sample>
	<xrdMeasurement measurementType="Scan" status="Completed" sampleMode="Reflection">
		<comment>
			<entry/>
		</comment>
		<usedWavelength intended="K-Alpha 1">
			<kAlpha1 unit="Angstrom">1.5405980</kAlpha1>
			<kAlpha2 unit="Angstrom">1.5444260</kAlpha2>
			<kBeta unit="Angstrom">1.3922500</kBeta>
			<ratioKAlpha2KAlpha1>0.5000</ratioKAlpha2KAlpha1>
		</usedWavelength>
		<incidentBeamPath>
			<radius unit="mm">240.00</radius>
			<xRayTube id="1010048" name="Empyrean Cu LFF HR (9430 033 7310x) DK402532">
				<tension unit="kV">45</tension>
				<current unit="mA">40</current>
				<anodeMaterial>Cu</anodeMaterial>
				<focus type="Line">
					<length unit="mm">12.0</length>
					<width unit="mm">0.4</width>
					<takeOffAngle unit="deg">4.4</takeOffAngle>
				</focus>
			</xRayTube>
			<xRayMirror id="27020009" name="Bragg-Brentano HD" hybrid="false">
				<crystal type="Graded" shape="Flat">BB/HD</crystal>
				<acceptanceAngle unit="deg">0.800</acceptanceAngle>
				<length unit="mm">55.3</length>
			</xRayMirror>
			<sollerSlit id="21010001" name="Soller slits 0.02 rad.">
				<opening unit="rad">0.0200</opening>
			</sollerSlit>
			<mask id="22030009" name="Fixed mask 10 mm">
				<width unit="mm">10.00</width>
			</mask>
			<antiScatterSlit id="22010003" name="Fixed slit 1°" xsi:type="fixedAntiScatterSlitType">
				<height unit="mm">1.52</height>
			</antiScatterSlit>
			<divergenceSlit id="22010005" name="Fixed slit 1/4°" xsi:type="fixedDivergenceSlitType">
				<distanceToSample unit="mm">140.00</distanceToSample>
				<height unit="mm">0.38</height>
			</divergenceSlit>
		</incidentBeamPath>
		<diffractedBeamPath>
			<radius unit="mm">240.00</radius>
			<antiScatterSlit id="22090004" name="AS slit 5.5 mm (X'Celerator)" xsi:type="fixedAntiScatterSlitType">
				<height unit="mm">5.50</height>
			</antiScatterSlit>
			<sollerSlit id="21020002" name="Large Soller slits 0.02 rad.">
				<opening unit="rad">0.0200</opening>
			</sollerSlit>
			<detector id="7010012" name="X'Celerator Scientific" xsi:type="rtmsDetectorType">
				<phd>
					<lowerLevel unit="%">38.5</lowerLevel>
					<upperLevel unit="%">80.0</upperLevel>
				</phd>
				<mode>Scanning</mode>
				<activeLength unit="deg">2.1221</activeLength>
			</detector>
		</diffractedBeamPath>
		<scan appendNumber="0" mode="Continuous" scanAxis="Gonio" status="Completed">
			<header>
				<startTimeStamp>2018-08-21T23:31:14-04:00</startTimeStamp>
				<endTimeStamp>2018-08-21T23:39:39-04:00</endTimeStamp>
				<author>
					<name>User</name>
				</author>
				<source>
					<applicationSoftware version="4.4a">Data Collector</applicationSoftware>
					<instrumentControlSoftware version="7.4  20131206">EMPYREAN</instrumentControlSoftware>
					<instrumentID>0000000011157113</instrumentID>
				</source>
			</header>
			<dataPoints>
				<positions axis="2Theta" unit="deg">
					<startPosition>3.00835563</startPosition>
					<endPosition>69.98712170</endPosition>
				</positions>
				<positions axis="Omega" unit="deg">
					<startPosition>1.50417782</startPosition>
					<endPosition>34.99356085</endPosition>
				</positions>
				<commonCountingTime unit="seconds">15.240</commonCountingTime>
				<intensities unit="counts">275 264 264 258 266 256 243 229 241 249 267 245 244 253 244 221 205 217 216 243 228 231 223 245 231 198 243 196 213 197 189 207 179 194 212 204 206 187 194 204 182 173 183 208 197 199 194 188 210 181 184 195 189 179 192 172 182 152 176 189 180 193 172 193 188 169 164 174 160 169 143 155 167 137 141 157 156 170 145 132 137 152 162 153 153 132 151 157 173 158 165 161 139 148 141 118 144 134 160 148 146 149 163 151 144 133 121 139 138 129 141 167 121 134 141 134 143 149 148 150 151 140 155 130 141 137 126 137 148 124 125 106 122 138 124 128 117 144 115 101 123 115 137 111 132 151 102 128 113 118 135 139 123 124 123 134 125 122 115 111 118 105 124 118 111 111 130 120 126 128 124 124 123 115 112 97 129 114 124 129 87 102 126 91 98 102 110 117 129 108 103 102 109 88 96 112 102 115 106 118 98 114 109 99 97 85 101 99 103 96 98 116 97 103 110 85 104 110 99 97 84 99 79 85 118 100 108 106 99 112 88 99 87 88 105 110 87 108 115 89 86 93 126 94 80 84 93 91 104 88 103 88 100 94 111 81 93 109 91 91 92 91 91 101 70 86 86 79 92 69 80 88 94 72 90 99 86 103 78 93 94 92 80 74 88 90 86 97 99 87 88 66 86 76 63 70 75 84 102 87 81 65 69 79 80 84 73 75 72 86 87 98 77 88 68 98 57 74 81 80 73 77 80 55 68 70 86 79 77 67 87 74 68 69 66 82 57 66 75 86 82 78 70 75 77 76 87 73 80 76 78 75 80 75 67 65 77 78 66 68 72 69 67 74 68 82 64 81 69 87 67 54 51 73 64 65 55 64 73 73 73 68 64 90 64 58 61 79 74 68 75 64 57 63 77 68 82 81 65 62 53 67 76 66 60 78 65 52 70 80 70 69 67 66 68 66 66 76 53 67 55 63 65 52 63 72 51 65 54 46 52 53 56 51 56 56 57 58 63 64 63 67 63 53 61 56 77 55 67 57 60 57 81 56 55 50 64 58 58 70 58 60 70 57 52 65 56 62 36 66 72 67 53 65 63 60 63 72 46 52 67 57 64 61 56 58 48 57 72 46 46 74 60 51 80 57 61 58 57 60 60 54 52 60 61 55 66 48 65 44 41 55 54 54 58 41 43 60 65 66 60 57 60 60 46 57 66 51 64 55 48 45 65 51 61 58 48 72 65 67 55 58 52 60 67 60 58 58 52 51 85 54 52 48 53 55 46 52 51 72 50 60 60 62 48 49 53 56 72 55 49 55 63 51 65 55 72 64 58 53 60 45 54 49 57 48 61 55 58 55 53 72 60 72 55 56 54 63 64 65 60 56 55 63 62 62 65 50 61 62 45 48 73 57 65 42 58 42 61 68 74 53 64 77 62 70 51 63 68 53 64 89 63 69 68 79 65 64 80 66 82 82 75 67 86 99 105 84 104 106 115 97 120 114 141 152 176 219 267 260 334 422 516 614 839 1161 1537 1758 1895 1564 1195 803 538 332 259 201 163 135 143 100 101 105 89 81 75 76 76 79 74 84 51 56 61 63 70 57 65 67 73 61 66 54 57 70 58 60 66 67 52 68 60 52 81 52 63 62 60 51 58 57 60 75 60 52 51 66 53 53 63 61 52 72 54 52 73 54 53 67 72 55 42 67 64 64 62 48 64 64 52 45 52 51 50 57 53 64 65 57 70 51 63 57 55 75 70 65 51 57 62 52 63 63 61 57 55 64 62 70 52 61 60 48 50 73 52 48 65 66 61 63 55 65 58 57 55 53 54 65 61 57 68 56 68 69 52 56 54 61 53 65 62 67 51 63 66 75 58 61 73 75 55 50 56 68 70 63 80 62 62 56 60 63 55 65 70 76 51 52 48 77 62 49 61 62 72 60 73 62 73 58 53 72 64 68 52 60 80 72 66 68 72 61 70 56 67 63 63 68 80 54 70 53 73 84 70 56 65 72 61 84 66 52 77 74 66 62 57 60 79 68 67 62 65 79 76 70 70 72 58 68 61 72 77 58 81 78 76 60 64 63 73 79 66 50 64 61 74 63 73 80 75 99 89 64 64 70 61 93 68 74 76 75 72 77 58 70 72 75 84 81 87 70 66 73 75 81 88 66 67 67 79 76 63 70 61 77 88 81 76 69 70 81 70 74 86 74 49 85 88 109 81 82 90 69 73 89 64 86 80 85 75 61 78 76 69 78 86 65 86 78 84 102 84 85 88 76 84 84 75 97 79 100 90 92 117 90 114 84 82 92 88 114 92 103 101 98 128 132 151 141 179 179 134 134 133 115 87 117 103 94 103 90 94 94 96 85 87 87 85 94 96 100 98 96 92 89 102 89 92 82 88 81 89 94 93 84 105 88 91 89 88 111 94 93 78 108 76 88 106 82 76 101 97 78 96 94 112 77 92 89 110 109 93 87 109 99 88 101 68 91 68 103 91 96 96 110 99 87 86 89 89 88 104 91 101 100 96 105 103 81 72 111 79 100 103 91 101 122 97 96 111 96 112 94 100 89 127 81 97 109 112 87 102 103 106 96 82 90 80 93 92 98 94 93 79 100 100 90 100 109 116 82 99 98 105 102 102 118 98 112 104 97 88 96 115 103 106 106 96 115 106 104 111 117 99 93 121 86 94 112 103 118 90 102 97 96 106 115 98 80 122 100 106 106 104 89 91 110 93 114 96 97 100 99 102 113 118 96 98 109 96 93 116 109 110 91 93 110 109 116 112 123 113 135 114 151 151 176 165 179 180 134 149 120 133 115 111 99 130 112 104 103 102 88 125 121 91 102 87 109 89 113 96 86 108 110 101 113 92 97 99 87 115 120 112 109 89 124 99 120 96 102 105 118 114 106 102 94 97 111 93 94 110 103 138 138 130 164 156 139 140 139 121 153 117 116 109 102 97 113 104 87 122 126 103 113 105 111 85 105 112 99 102 102 97 118 91 91 114 106 108 82 108 99 91 112 109 113 111 111 99 103 109 92 110 108 87 106 85 81 104 98 124 96 87 99 103 102 100 113 114 112 108 101 109 103 113 114 86 91 97 104 84 96 122 89 97 112 79 101 113 97 101 103 109 108 96 92 78 99 86 103 99 112 125 110 92 102 121 92 106 109 99 89 89 92 100 105 110 93 105 98 88 97 94 91 90 101 93 100 112 94 75 104 93 79 99 104 99 99 97 100 103 100 90 100 94 94 93 103 111 98 89 102 92 108 112 91 100 103 73 91 112 85 98 109 112 92 105 102 92 98 96 80 97 103 81 88 79 112 101 90 111 89 90 106 87 97 100 84 93 69 91 96 102 93 94 99 112 115 102 105 99 93 92 103 89 102 99 116 85 105 92 103 120 117 97 128 108 94 106 93 124 134 118 144 135 164 188 169 149 140 160 160 148 145 135 172 157 184 241 266 455 609 708 773 626 604 493 472 358 292 213 157 116 121 114 116 108 96 108 86 86 90 92 111 92 97 99 106 100 118 92 90 98 104 85 91 99 91 80 88 86 75 88 104 97 79 78 82 93 105 90 82 84 81 96 79 79 92 99 90 93 82 77 101 73 77 63 87 106 99 80 88 89 88 90 102 96 98 84 82 84 99 108 92 80 91 91 73 97 78 87 94 87 78 86 82 68 91 82 69 78 86 72 74 69 87 82 96 81 74 92 80 99 96 63 92 76 97 97 66 108 90 88 92 87 73 84 97 79 88 97 75 90 88 77 82 102 78 86 89 89 88 98 72 65 79 85 92 77 91 82 73 93 72 81 81 92 72 81 96 96 78 87 82 72 81 78 74 67 88 75 81 90 79 86 72 72 85 73 69 90 76 69 88 80 79 81 75 97 79 93 88 89 91 88 97 81 106 90 103 91 103 110 141 170 218 189 233 281 286 256 207 199 185 157 151 117 97 81 82 84 65 90 72 87 76 77 81 84 77 64 73 63 65 78 87 72 88 79 78 72 66 72 60 81 56 67 79 81 72 74 84 76 68 69 68 63 72 67 70 90 89 97 60 62 61 63 62 61 61 76 73 65 53 73 75 73 48 73 75 55 93 69 77 69 42 73 69 78 73 64 62 60 61 96 70 68 64 58 80 62 57 80 73 70 67 60 77 64 86 57 70 64 56 65 68 67 55 72 65 49 60 77 87 66 58 62 61 64 60 62 64 58 54 55 57 69 64 60 75 61 54 70 70 68 53 62 75 54 64 50 61 61 57 62 64 66 68 66 78 55 60 44 57 65 67 54 51 65 57 56 70 54 60 51 50 45 58 63 78 60 62 63 66 62 66 64 51 56 72 85 103 86 97 84 76 81 68 69 65 56 66 53 54 64 62 68 63 54 54 48 60 58 67 67 55 58 58 48 61 52 62 53 48 48 50 51 52 58 64 48 51 54 55 42 57 60 34 58 63 62 52 48 56 54 49 65 46 43 52 60 60 37 46 62 48 44 44 50 56 65 54 61 60 64 48 57 55 60 52 68 66 52 45 64 43 42 40 54 34 52 54 61 56 50 46 57 48 50 44 33 45 58 62 41 48 52 62 64 56 38 56 42 54 37 44 61 46 45 42 40 51 50 50 53 42 51 44 60 62 50 53 42 58 60 40 50 37 54 50 44 52 52 46 36 48 48 40 41 42 51 44 52 56 45 53 40 53 37 45 40 50 46 57 50 41 41 40 45 51 57 54 69 43 44 69 43 45 50 52 60 44 43 43 37 56 50 49 42 41 44 46 37 54 43 48 46 41 37 49 54 54 36 57 45 52 36 38 40 42 48 36 40 42 42 46 32 41 44 39 38 44 48 30 44 39 56 56 40 37 46 44 44 39 62 52 34 48 37 38 39 41 46 44 33 48 45 46 43 41 31 33 37 28 40 40 34 30 46 41 40 41 49 36 37 42 48 40 39 55 38 37 37 56 46 50 50 48 45 64 49 36 46 39 43 45 45 39 45 43 39 51 38 40 34 42 43 52 42 57 49 38 49 36 43 41 32 43 50 43 52 52 37 30 37 33 36 37 49 44 54 46 34 40 46 45 61 43 60 74 69 77 64 79 63 65 72 64 80 58 57 96 88 120 103 96 93 60 62 62 79 64 61 51 50 68 45 30 50 55 41 43 49 51 53 45 49 41 49 49 40 44 41 57 34 55 49 41 54 46 39 46 37 40 46 44 38 58 38 46 42 42 42 38 46 32 46 42 44 46 40 28 46 34 39 43 39 58 44 44 41 40 44 44 50 37 55 50 52 34 43 39 51 39 36 48 39 50 48 31 40 42 37 43 43 43 53 34 39 44 46 38 44 40 44 50 41 54 42 40 43 40 43 54 45 52 51 55 64 67 48 60 54 63 48 62 51 52 45 48 39 38 36 46 42 37 39 42 49 58 64 50 49 58 53 69 64 60 60 72 69 61 63 60 76 79 82 75 60 67 57 72 54 57 56 64 46 38 48 40 44 33 37 39 36 37 28 54 50 44 43 50 37 46 46 39 32 40 44 48 44 51 45 28 42 46 53 31 51 34 50 46 42 50 41 49 51 44 38 34 36 36 39 39 45 49 43 39 44 39 54 37 53 36 43 41 39 40 38 30 36 41 34 37 51 41 33 33 46 27 46 45 49 40 36 41 41 43 41 41 45 38 40 42 43 45 28 43 33 36 41 43 34 40 33 43 38 40 43 31 34 45 36 37 31 30 48 46 33 45 38 32 39 37 54 37 43 40 62 45 36 49 38 38 60 44 32 43 36 54 39 30 41 46 44 48 48 42 33 46 39 48 31 50 48 51 37 43 38 51 46 48 21 41 31 39 30 44 40 38 38 38 33 31 38 44 43 46 45 33 27 34 43 44 46 44 27 27 40 25 34 46 37 39 50 37 33 48 46 32 39 20 46 44 31 37 36 41 40 38 38 39 44 42 44 43 38 48 37 39 38 44 38 37 37 37 41 50 38 33 41 36 31 30 27 30 41 24 32 45 31 28 65 37 32 36 38 37 34 33 31 40 41 45 48 37 52 52 30 44 36 40 44 37 43 31 28 33 36 33 40 49 32 50 36 43 44 38 27 28 30 33 44 52 40 46 41 40 50 26 41 38 39 36 54 40 44 37 39 32 42 32 42 32 36 37 28 42 19 36 31 36 39 28 39 39 31 37 30 36 32 32 29 30 38 38 33 38 32 28 48 39 32 44 42 45 40 33 37 33 29 39 29 42 46 41 37 36 28 33 22 32 40 30 41 34 43 48 30 38 22 43 42 38 38 39 43 31 38 36 28 32 32 33 25 52 33 37 36 41 36 32 40 34 38 31 25 43 40 29 28 32 38 38 43 41 37 33 27 33 37 45 46 40 42 32 38 31 33 34 31 48 50 60 48 54 43 46 42 53 58 44 62 39 28 34 36 31 49 42 32 46 32 37 29 34 38 37 44 38 27 33 43 30 37 34 38 42 34 33 33 31 29 26 30 37 50 36 31 31 31 34 38 36 26 38 36 41 37 30 37 28 28 32 40 44 39 27 29 48 38 31 44 30 28 30 29 32 29 34 31 29 32 32 30 36 32 40 30 48 42 28 46 28 36 36 36 39 31 31 38 28 33 42 34 34 29 37 33 33 45 41 37 36 31 40 41 24 36 42 36 39 45 38 26 32 27 30 40 34 30 26 42 32 34 31 38 37 26 34 31 38 34 40 31 31 42 42 42 41 39 40 37 36 44 29 37 22 26 30 29 41 30 33 41 27 45 31 38 36 46 48 36 42 29 31 34 28 37 42 37 36 39 43 27 29 42 26 31 50 28 34 25 27 26 28 29 36 38 40 31 25 29 28 30 32 31 33 37 40 33 27 43 30 40 28 38 38 30 20 32 29 38 22 44 36 36 33 40 33 20 37 32 37 36 45 25 38 37 38 38 25 40 30 29 29 33 30 36 41 31 48 46 38 41 22 37 37 36 43 30 29 46 36 36 34 33 46 26 43 42 31 36 30 29 38 36 44 32 46 40 37 34 37 39 30 30 44 36 37 32 37 36 26 34 32 37 32 22 34 33 42 40 34 43 34 32 32 37 37 36 38 41 37 29 40 32 28 38 39 43 31 39 33 33 36 30 24 27 25 24 26 30 30 28 29 36 41 30 42 34 36 51 34 22 28 32 27 39 27 30 33 33 36 31 46 33 37 29 34 37 45 40 40 42 40 38 33 34 26 38 27 42 37 32 39 31 30 38 29 37 34 29 27 36 43 28 27 39 40 38 29 32 37 31 29 31 32 40 32 38 42 28 22 25 30 27 39 32 32 28 39 26 28 43 28 28 44 33 32 27 36 39 27 36 39 36 33 51 39 48 31 30 39 39 33 34 27 40 37 39 34 60 46 27 26 25 39 40 38 40 36 26 39 32 36 44 32 36 40 36 31 32 29 31 37 39 28 31 40 40 32 34 36 40 46 37 36 37 33 29 36 39 30 30 20 34 38 33 30 38 37 39 42 32 41 30 42 33 32 38 21 30 24 30 30 31 40 25 43 39 31 30 40 27 42 36 46 39 37 58 43 43 43 48 55 42 49 48 44 40 38 40 53 30 45 42 26 31 25 33 33 40 34 30 48 28 42 46 27 37 24 37 39 37 30 34 31 34 39 48 24 31 27 37 27 36 40 33 36 39 28 40 30 30 46 30 40 31 37 28 30 37 38 30 29 30 32 31 34 26 38 36 34 31 36 22 39 52 34 31 38 37 39 33 42 40 30 24 41 34 39 34 30 29 43 37 42 42 21 32 28 39 29 21 40 33 39 36 36 37 40 41 39 46 48 41 42 36 51 46 46 56 51 51 45 46 43 43 43 50 45 34 45 38 30 37 43 33 26 38 40 33 44 38 30 40 38 39 42 29 43 28 29 30 36 43 41 31 19 26 25 36 37 31 30 46 38 28 29 41 31 36 34 34 34 37 41 45 32 38 33 36 29 38 45 27 29 32 40 32 38 37 41 24 38 27 36 41 39 29 29 39 33 32 38 39 38 33 32 38 24 31 45 36 41 40 45 26 38 44 21 34 32 27 34 34 29 30 27 25 42 43 37 37 54 43 42 31 48 44 37 41 33 49 39 33 36 48 41 42 28 48 32 33 36 38 50 36 33 30 32 39 29 34 25 43 36 32 27 32 39 34 45 36 39 30 41 34 33 39 36 28 29 29 34 33 27 30 38 33 41 29 37 38 41 33 29 29 25 26 29 32 27 31 31 50 31 25 36 28 27 25 38 39 40 33 26 48 31 33 32 37 30 44 30 34 40 32 39 45 30 29 17 31 28 37 39 38 41 29 27 39 33 32 32 27 30 30 30 32 37 39 40 36 34 20 32 32 27 17 48 31 31 28 44 34 32 36 38 39 27 21 34 29 33 37 27 41 36 28 30 34 32 43 28 33 20 43 34 32 28 38 36 25 30 38 24 31 36 25 26 32 37 32 31 41 32 34 19 26 36 34 29 40 24 41 39 36 20 34 40 31 29 39 22 37 30 37 33 42 31 38 36 33 31 42 45 32 39 33 22 40 32 31 36 30 32 36 30 30 42 30 31 27 21 26 39 37 39 31 31 32 34 43 38 41 39 34 41 31 30 32 18 36 40 34 33 31 41 37 42 36 34 26 34 42 27 34 37 40 38 42 31 34 34 28 41 31 34 30 33 31 24 38 29 41 29 34 36 32 33 38 34 26 45 27 38 32 29 29 24 37 34 37 30 21 36 26 34 36 36 37 34 27 29 28 44 31 22 42 24 37 44 28 29 46 30 22 29 29 25 36 19 27 31 28 32 27 25 28 30 28 34 31 39 30 31 50 32 48 39 40 43 36 39 38 37 34 33 34 38 33 27 19 32 34 33 39 38 41 32 27 30 20 36 33 33 28 25 34 27 41 27 25 36 37 31 18 31 33 34 29 32 27 36 19 19 40 33 28 22 32 36 24 29 26 34 21 31 32 42 28 32 27 36 32 20 28 32 26 36 16 28 27 36 25 31 31 29 31 28 27 44 37 28 27 33 20 30 26 26 29 28 39 34 25</intensities>
			</dataPoints>
		</scan>
	</xrdMeasurement>
</xrdMeasurements>